Workbook

Sheet Состав прибора
A20: Индустриальный компьютер
A21: SBC_35_2C3_1_E1E001CPU1E | B21: 1 | C21: 2049
A22: IB_2RS232_E1N002INF1 | B22: 2 | C22: 202
A23: SBC_DIO_E1N004INF1 | B23: 1 | C23: ?
A25: Модульный компьютер
A26: EM-PCIE104-CPU_E1E001CPU1E | B26: 1 | C26: 1948
A27: PCIe104_INF_E1N001INF1 | B27: 1 | C27: 1068
A28: PCIe104_INF2_E1N006INF1 | B28: 1 | C28: 326
A29: PCIe104_CON_E1N005INF1 | B29: 1 | C29: 195
A30: PCIe104_PSU_E1N001PWR1 | B30: 1 | C30: 262
A32: Панельный компьютер
A33: IB_2CAN_E1N003INF1 | B33: 1 | C33: 132
A34: IB_2RS232_E1N002INF1 | B34: 1 | C34: 202
A35: C2B004CPU2 | B35: 1 | C35: ?

Sheet По проектам
H1: 1 | I1: 1 | J1: 1 | K1: 1 | L1: 1
A2: Manuf | B2: Замена | C2: Part Number | D2: Итого | E2: C2B004CPU2 | F2: SBC_DIO_E1N004INF1 | G2: SBC_35_2C3_1_E1E001CPU1E | H2: PCIe104_PSU_E1N001PWR1 | I2: PCIe104_INF2_E1N006INF1 | J2: PCIe104_CON_E1N005INF1 | K2: EM-PCIE104-CPU_E1E001CPU1E | L2: PCIe104_INF_E1N001INF1 | M2: IB_2RS232_E1N002INF1 | N2: IB_2CAN_E1N003INF1
A3: 3PEAK | C3: TPT3232E-TS3R | D3: =SUM(E3:N3) -> 0 | E3: ='По платам'!C5*$E$1 -> 0 | F3: ='По платам'!D5*$F$1 -> 0 | G3: ='По платам'!E5*$G$1 -> 0 | H3: ='По платам'!F5*$H$1 -> 0 | I3: ='По платам'!G5*$I$1 -> 0 | J3: ='По платам'!H5*$J$1 -> 0 | K3: ='По платам'!I5*$K$1 -> 0 | L3: ='По платам'!J5*$L$1 -> 0 | M3: ='По платам'!K5*$M$1 -> 0 | N3: ='По платам'!L5*'Состав прибора'!$B$16 -> 0
A4: 3PEAK | C4: TPT71042-SOAR | D4: =SUM(E4:N4) -> 1 | E4: ='По платам'!C6*$E$1 -> 0 | F4: ='По платам'!D6*$F$1 -> 0 | G4: ='По платам'!E6*$G$1 -> 0 | H4: ='По платам'!F6*$H$1 -> 0 | I4: ='По платам'!G6*$I$1 -> 0 | J4: ='По платам'!H6*$J$1 -> 0 | K4: ='По платам'!I6*$K$1 -> 0 | L4: ='По платам'!J6*$L$1 -> 1 | M4: ='По платам'!K6*$M$1 -> 0 | N4: ='По платам'!L6*'Состав прибора'!$B$16 -> 0
A5: 3PEAK | C5: TPT7762-SSAR | D5: =SUM(E5:N5) -> 12 | E5: ='По платам'!C7*$E$1 -> 0 | F5: ='По платам'!D7*$F$1 -> 0 | G5: ='По платам'!E7*$G$1 -> 0 | H5: ='По платам'!F7*$H$1 -> 0 | I5: ='По платам'!G7*$I$1 -> 8 | J5: ='По платам'!H7*$J$1 -> 0 | K5: ='По платам'!I7*$K$1 -> 0 | L5: ='По платам'!J7*$L$1 -> 4 | M5: ='По платам'!K7*$M$1 -> 0 | N5: ='По платам'!L7*'Состав прибора'!$B$16 -> 0
A6: 3PEAK | C6: TPV811S-4LTR | D6: =SUM(E6:N6) -> 0 | E6: ='По платам'!C8*$E$1 -> 0 | F6: ='По платам'!D8*$F$1 -> 0 | G6: ='По платам'!E8*$G$1 -> 0 | H6: ='По платам'!F8*$H$1 -> 0 | I6: ='По платам'!G8*$I$1 -> 0 | J6: ='По платам'!H8*$J$1 -> 0 | K6: ='По платам'!I8*$K$1 -> 0 | L6: ='По платам'!J8*$L$1 -> 0 | M6: ='По платам'!K8*$M$1 -> 0 | N6: ='По платам'!L8*'Состав прибора'!$B$16 -> 0
A7: Abracon Corporation | C7: ABM11W-32.0000MHZ-8-D1X-T3 | D7: =SUM(E7:N7) -> 0 | E7: ='По платам'!C9*$E$1 -> 0 | F7: ='По платам'!D9*$F$1 -> 0 | G7: ='По платам'!E9*$G$1 -> 0 | H7: ='По платам'!F9*$H$1 -> 0 | I7: ='По платам'!G9*$I$1 -> 0 | J7: ='По платам'!H9*$J$1 -> 0 | K7: ='По платам'!I9*$K$1 -> 0 | L7: ='По платам'!J9*$L$1 -> 0 | M7: ='По платам'!K9*$M$1 -> 0 | N7: ='По платам'!L9*'Состав прибора'!$B$16 -> 0
A8: Abracon Corporation | C8: ABM8-24.000MHZ-D1G-T | D8: =SUM(E8:N8) -> 1 | E8: ='По платам'!C10*$E$1 -> 0 | F8: ='По платам'!D10*$F$1 -> 0 | G8: ='По платам'!E10*$G$1 -> 0 | H8: ='По платам'!F10*$H$1 -> 0 | I8: ='По платам'!G10*$I$1 -> 0 | J8: ='По платам'!H10*$J$1 -> 0 | K8: ='По платам'!I10*$K$1 -> 0 | L8: ='По платам'!J10*$L$1 -> 1 | M8: ='По платам'!K10*$M$1 -> 0 | N8: ='По платам'!L10*'Состав прибора'!$B$16 -> 0
A9: Abracon Corporation | C9: ABM8-25.000MHZ-12-D1X-T | D9: =SUM(E9:N9) -> 8 | E9: ='По платам'!C11*$E$1 -> 0 | F9: ='По платам'!D11*$F$1 -> 0 | G9: ='По платам'!E11*$G$1 -> 0 | H9: ='По платам'!F11*$H$1 -> 0 | I9: ='По платам'!G11*$I$1 -> 0 | J9: ='По платам'!H11*$J$1 -> 0 | K9: ='По платам'!I11*$K$1 -> 3 | L9: ='По платам'!J11*$L$1 -> 5 | M9: ='По платам'!K11*$M$1 -> 0 | N9: ='По платам'!L11*'Состав прибора'!$B$16 -> 0
A10: Abracon Corporation | C10: ABM8W-12.0000MHZ-8-D1X-T3 | D10: =SUM(E10:N10) -> 5 | E10: ='По платам'!C12*$E$1 -> 0 | F10: ='По платам'!D12*$F$1 -> 0 | G10: ='По платам'!E12*$G$1 -> 0 | H10: ='По платам'!F12*$H$1 -> 0 | I10: ='По платам'!G12*$I$1 -> 2 | J10: ='По платам'!H12*$J$1 -> 0 | K10: ='По платам'!I12*$K$1 -> 1 | L10: ='По платам'!J12*$L$1 -> 2 | M10: ='По платам'!K12*$M$1 -> 0 | N10: ='По платам'!L12*'Состав прибора'!$B$16 -> 0
A11: Abracon Corporation | C11: ASDMB-14.31818MHZ-LY-T | D11: =SUM(E11:N11) -> 1 | E11: ='По платам'!C13*$E$1 -> 0 | F11: ='По платам'!D13*$F$1 -> 0 | G11: ='По платам'!E13*$G$1 -> 0 | H11: ='По платам'!F13*$H$1 -> 0 | I11: ='По платам'!G13*$I$1 -> 0 | J11: ='По платам'!H13*$J$1 -> 0 | K11: ='По платам'!I13*$K$1 -> 1 | L11: ='По платам'!J13*$L$1 -> 0 | M11: ='По платам'!K13*$M$1 -> 0 | N11: ='По платам'!L13*'Состав прибора'!$B$16 -> 0
A12: Abracon Corporation | C12: AX3DCF1-156.2500 | D12: =SUM(E12:N12) -> 1 | E12: ='По платам'!C14*$E$1 -> 0 | F12: ='По платам'!D14*$F$1 -> 0 | G12: ='По платам'!E14*$G$1 -> 0 | H12: ='По платам'!F14*$H$1 -> 0 | I12: ='По платам'!G14*$I$1 -> 0 | J12: ='По платам'!H14*$J$1 -> 0 | K12: ='По платам'!I14*$K$1 -> 1 | L12: ='По платам'!J14*$L$1 -> 0 | M12: ='По платам'!K14*$M$1 -> 0 | N12: ='По платам'!L14*'Состав прибора'!$B$16 -> 0
A13: Adam Tech | C13: LHA-02-TS | D13: =SUM(E13:N13) -> 0 | E13: ='По платам'!C15*$E$1 -> 0 | F13: ='По платам'!D15*$F$1 -> 0 | G13: ='По платам'!E15*$G$1 -> 0 | H13: ='По платам'!F15*$H$1 -> 0 | I13: ='По платам'!G15*$I$1 -> 0 | J13: ='По платам'!H15*$J$1 -> 0 | K13: ='По платам'!I15*$K$1 -> 0 | L13: ='По платам'!J15*$L$1 -> 0 | M13: ='По платам'!K15*$M$1 -> 0 | N13: ='По платам'!L15*'Состав прибора'!$B$16 -> 0
A14: Advanced Monolithic Systems | C14: AMS1117-3.3 | D14: =SUM(E14:N14) -> 0 | E14: ='По платам'!C16*$E$1 -> 0 | F14: ='По платам'!D16*$F$1 -> 0 | G14: ='По платам'!E16*$G$1 -> 0 | H14: ='По платам'!F16*$H$1 -> 0 | I14: ='По платам'!G16*$I$1 -> 0 | J14: ='По платам'!H16*$J$1 -> 0 | K14: ='По платам'!I16*$K$1 -> 0 | L14: ='По платам'!J16*$L$1 -> 0 | M14: ='По платам'!K16*$M$1 -> 0 | N14: ='По платам'!L16*'Состав прибора'!$B$16 -> 0
... A425: XW-ETLINK | C425: XWRJ-1108D10147 | D425: =SUM(E425:N425) -> 0 | E425: ='По платам'!C427*$E$1 -> 0 | F425: ='По платам'!D427*$F$1 -> 0 | G425: ='По платам'!E427*$G$1 -> 0 | H425: ='По платам'!F427*$H$1 -> 0 | I425: ='По платам'!G427*$I$1 -> 0 | J425: ='По платам'!H427*$J$1 -> 0 | K425: ='По платам'!I427*$K$1 -> 0 | L425: ='По платам'!J427*$L$1 -> 0 | M425: ='По платам'!K427*$M$1 -> 0 | N425: ='По платам'!L427*'Состав прибора'!$B$16 -> 0
A426: Yageo | B426: RC0201FR-070RL | C426: AC0201FR-070RL | D426: =SUM(E426:N426) -> 1 | E426: ='По платам'!C428*$E$1 -> 0 | F426: ='По платам'!D428*$F$1 -> 0 | G426: ='По платам'!E428*$G$1 -> 0 | H426: ='По платам'!F428*$H$1 -> 0 | I426: ='По платам'!G428*$I$1 -> 0 | J426: ='По платам'!H428*$J$1 -> 0 | K426: ='По платам'!I428*$K$1 -> 1 | L426: ='По платам'!J428*$L$1 -> 0 | M426: ='По платам'!K428*$M$1 -> 0 | N426: ='По платам'!L428*'Состав прибора'!$B$16 -> 0
A427: Yageo | B427: RC0201FR-07100KL | C427: AC0201FR-07100KL | D427: =SUM(E427:N427) -> 50 | E427: ='По платам'!C429*$E$1 -> 0 | F427: ='По платам'!D429*$F$1 -> 0 | G427: ='По платам'!E429*$G$1 -> 0 | H427: ='По платам'!F429*$H$1 -> 0 | I427: ='По платам'!G429*$I$1 -> 0 | J427: ='По платам'!H429*$J$1 -> 0 | K427: ='По платам'!I429*$K$1 -> 50 | L427: ='По платам'!J429*$L$1 -> 0 | M427: ='По платам'!K429*$M$1 -> 0 | N427: ='По платам'!L429*'Состав прибора'!$B$16 -> 0
A428: Yageo | B428: RC0201FR-07100RL | C428: AC0201FR-07100RL | D428: =SUM(E428:N428) -> 2 | E428: ='По платам'!C430*$E$1 -> 0 | F428: ='По платам'!D430*$F$1 -> 0 | G428: ='По платам'!E430*$G$1 -> 0 | H428: ='По платам'!F430*$H$1 -> 0 | I428: ='По платам'!G430*$I$1 -> 0 | J428: ='По платам'!H430*$J$1 -> 0 | K428: ='По платам'!I430*$K$1 -> 2 | L428: ='По платам'!J430*$L$1 -> 0 | M428: ='По платам'!K430*$M$1 -> 0 | N428: ='По платам'!L430*'Состав прибора'!$B$16 -> 0
A429: Yageo | B429: RC0201FR-0710KL | C429: AC0201FR-0710KL | D429: =SUM(E429:N429) -> 57 | E429: ='По платам'!C431*$E$1 -> 0 | F429: ='По платам'!D431*$F$1 -> 0 | G429: ='По платам'!E431*$G$1 -> 0 | H429: ='По платам'!F431*$H$1 -> 0 | I429: ='По платам'!G431*$I$1 -> 0 | J429: ='По платам'!H431*$J$1 -> 0 | K429: ='По платам'!I431*$K$1 -> 54 | L429: ='По платам'!J431*$L$1 -> 3 | M429: ='По платам'!K431*$M$1 -> 0 | N429: ='По платам'!L431*'Состав прибора'!$B$16 -> 0
A430: Yageo | B430: RC0201FR-0712K1L | C430: AC0201FR-0712K1L | D430: =SUM(E430:N430) -> 2 | E430: ='По платам'!C432*$E$1 -> 0 | F430: ='По платам'!D432*$F$1 -> 0 | G430: ='По платам'!E432*$G$1 -> 0 | H430: ='По платам'!F432*$H$1 -> 0 | I430: ='По платам'!G432*$I$1 -> 0 | J430: ='По платам'!H432*$J$1 -> 0 | K430: ='По платам'!I432*$K$1 -> 2 | L430: ='По платам'!J432*$L$1 -> 0 | M430: ='По платам'!K432*$M$1 -> 0 | N430: ='По платам'!L432*'Состав прибора'!$B$16 -> 0
A431: Yageo | B431: RC0201FR-071KL | C431: AC0201FR-071KL | D431: =SUM(E431:N431) -> 0 | E431: ='По платам'!C433*$E$1 -> 0 | F431: ='По платам'!D433*$F$1 -> 0 | G431: ='По платам'!E433*$G$1 -> 0 | H431: ='По платам'!F433*$H$1 -> 0 | I431: ='По платам'!G433*$I$1 -> 0 | J431: ='По платам'!H433*$J$1 -> 0 | K431: ='По платам'!I433*$K$1 -> 0 | L431: ='По платам'!J433*$L$1 -> 0 | M431: ='По платам'!K433*$M$1 -> 0 | N431: ='По платам'!L433*'Состав прибора'!$B$16 -> 0
A432: Yageo | B432: RC0201FR-07402RL | C432: AC0201FR-07402RL | D432: =SUM(E432:N432) -> 0 | E432: ='По платам'!C434*$E$1 -> 0 | F432: ='По платам'!D434*$F$1 -> 0 | G432: ='По платам'!E434*$G$1 -> 0 | H432: ='По платам'!F434*$H$1 -> 0 | I432: ='По платам'!G434*$I$1 -> 0 | J432: ='По платам'!H434*$J$1 -> 0 | K432: ='По платам'!I434*$K$1 -> 0 | L432: ='По платам'!J434*$L$1 -> 0 | M432: ='По платам'!K434*$M$1 -> 0 | N432: ='По платам'!L434*'Состав прибора'!$B$16 -> 0
A433: Yageo | B433: RC0201FR-0749K9L | C433: AC0201FR-0749K9L | D433: =SUM(E433:N433) -> 1 | E433: ='По платам'!C435*$E$1 -> 0 | F433: ='По платам'!D435*$F$1 -> 0 | G433: ='По платам'!E435*$G$1 -> 0 | H433: ='По платам'!F435*$H$1 -> 0 | I433: ='По платам'!G435*$I$1 -> 0 | J433: ='По платам'!H435*$J$1 -> 0 | K433: ='По платам'!I435*$K$1 -> 1 | L433: ='По платам'!J435*$L$1 -> 0 | M433: ='По платам'!K435*$M$1 -> 0 | N433: ='По платам'!L435*'Состав прибора'!$B$16 -> 0
A434: Yageo | B434: RC0201FR-0749R9L | C434: AC0201FR-0749R9L | D434: =SUM(E434:N434) -> 59 | E434: ='По платам'!C436*$E$1 -> 0 | F434: ='По платам'!D436*$F$1 -> 0 | G434: ='По платам'!E436*$G$1 -> 0 | H434: ='По платам'!F436*$H$1 -> 0 | I434: ='По платам'!G436*$I$1 -> 0 | J434: ='По платам'!H436*$J$1 -> 0 | K434: ='По платам'!I436*$K$1 -> 59 | L434: ='По платам'!J436*$L$1 -> 0 | M434: ='По платам'!K436*$M$1 -> 0 | N434: ='По платам'!L436*'Состав прибора'!$B$16 -> 0
A435: Yageo | B435: RC0201FR-074K7L | C435: AC0201FR-074K7L | D435: =SUM(E435:N435) -> 5 | E435: ='По платам'!C437*$E$1 -> 0 | F435: ='По платам'!D437*$F$1 -> 0 | G435: ='По платам'!E437*$G$1 -> 0 | H435: ='По платам'!F437*$H$1 -> 0 | I435: ='По платам'!G437*$I$1 -> 0 | J435: ='По платам'!H437*$J$1 -> 0 | K435: ='По платам'!I437*$K$1 -> 5 | L435: ='По платам'!J437*$L$1 -> 0 | M435: ='По платам'!K437*$M$1 -> 0 | N435: ='По платам'!L437*'Состав прибора'!$B$16 -> 0
A436: Yageo | B436: RC0201FR-07510RL | C436: AC0201FR-07510RL | D436: =SUM(E436:N436) -> 1 | E436: ='По платам'!C438*$E$1 -> 0 | F436: ='По платам'!D438*$F$1 -> 0 | G436: ='По платам'!E438*$G$1 -> 0 | H436: ='По платам'!F438*$H$1 -> 0 | I436: ='По платам'!G438*$I$1 -> 0 | J436: ='По платам'!H438*$J$1 -> 0 | K436: ='По платам'!I438*$K$1 -> 1 | L436: ='По платам'!J438*$L$1 -> 0 | M436: ='По платам'!K438*$M$1 -> 0 | N436: ='По платам'!L438*'Состав прибора'!$B$16 -> 0
A437: Yageo | B437: RC0201FR-0751KL | C437: AC0201FR-0751KL | D437: =SUM(E437:N437) -> 3 | E437: ='По платам'!C439*$E$1 -> 0 | F437: ='По платам'!D439*$F$1 -> 0 | G437: ='По платам'!E439*$G$1 -> 0 | H437: ='По платам'!F439*$H$1 -> 0 | I437: ='По платам'!G439*$I$1 -> 0 | J437: ='По платам'!H439*$J$1 -> 0 | K437: ='По платам'!I439*$K$1 -> 3 | L437: ='По платам'!J439*$L$1 -> 0 | M437: ='По платам'!K439*$M$1 -> 0 | N437: ='По платам'!L439*'Состав прибора'!$B$16 -> 0
... A503: Yageo | B503: RC1210FR-07270RL | C503: AC1210FR-07270RL | D503: =SUM(E503:N503) -> 2 | E503: ='По платам'!C505*$E$1 -> 0 | F503: ='По платам'!D505*$F$1 -> 0 | G503: ='По платам'!E505*$G$1 -> 0 | H503: ='По платам'!F505*$H$1 -> 0 | I503: ='По платам'!G505*$I$1 -> 0 | J503: ='По платам'!H505*$J$1 -> 0 | K503: ='По платам'!I505*$K$1 -> 0 | L503: ='По платам'!J505*$L$1 -> 2 | M503: ='По платам'!K505*$M$1 -> 0 | N503: ='По платам'!L505*'Состав прибора'!$B$16 -> 0
A504: Yageo | C504: CC0201JRNPO9BN101 | D504: =SUM(E504:N504) -> 16 | E504: ='По платам'!C506*$E$1 -> 0 | F504: ='По платам'!D506*$F$1 -> 0 | G504: ='По платам'!E506*$G$1 -> 0 | H504: ='По платам'!F506*$H$1 -> 0 | I504: ='По платам'!G506*$I$1 -> 0 | J504: ='По платам'!H506*$J$1 -> 0 | K504: ='По платам'!I506*$K$1 -> 11 | L504: ='По платам'!J506*$L$1 -> 5 | M504: ='По платам'!K506*$M$1 -> 0 | N504: ='По платам'!L506*'Состав прибора'!$B$16 -> 0
A505: Yageo | C505: CC0201JRNPO9BN330 | D505: =SUM(E505:N505) -> 0 | E505: ='По платам'!C507*$E$1 -> 0 | F505: ='По платам'!D507*$F$1 -> 0 | G505: ='По платам'!E507*$G$1 -> 0 | H505: ='По платам'!F507*$H$1 -> 0 | I505: ='По платам'!G507*$I$1 -> 0 | J505: ='По платам'!H507*$J$1 -> 0 | K505: ='По платам'!I507*$K$1 -> 0 | L505: ='По платам'!J507*$L$1 -> 0 | M505: ='По платам'!K507*$M$1 -> 0 | N505: ='По платам'!L507*'Состав прибора'!$B$16 -> 0
A506: Yageo | C506: CC0201JRX7R8BB221 | D506: =SUM(E506:N506) -> 8 | E506: ='По платам'!C508*$E$1 -> 0 | F506: ='По платам'!D508*$F$1 -> 0 | G506: ='По платам'!E508*$G$1 -> 0 | H506: ='По платам'!F508*$H$1 -> 0 | I506: ='По платам'!G508*$I$1 -> 0 | J506: ='По платам'!H508*$J$1 -> 4 | K506: ='По платам'!I508*$K$1 -> 4 | L506: ='По платам'!J508*$L$1 -> 0 | M506: ='По платам'!K508*$M$1 -> 0 | N506: ='По платам'!L508*'Состав прибора'!$B$16 -> 0
A507: Yageo | C507: CC0201KRX7R8BB103 | D507: =SUM(E507:N507) -> 65 | E507: ='По платам'!C509*$E$1 -> 0 | F507: ='По платам'!D509*$F$1 -> 0 | G507: ='По платам'!E509*$G$1 -> 0 | H507: ='По платам'!F509*$H$1 -> 0 | I507: ='По платам'!G509*$I$1 -> 3 | J507: ='По платам'!H509*$J$1 -> 0 | K507: ='По платам'!I509*$K$1 -> 42 | L507: ='По платам'!J509*$L$1 -> 20 | M507: ='По платам'!K509*$M$1 -> 0 | N507: ='По платам'!L509*'Состав прибора'!$B$16 -> 0
A508: Yageo | C508: CC0201KRX7R9BB102 | D508: =SUM(E508:N508) -> 13 | E508: ='По платам'!C510*$E$1 -> 0 | F508: ='По платам'!D510*$F$1 -> 0 | G508: ='По платам'!E510*$G$1 -> 0 | H508: ='По платам'!F510*$H$1 -> 0 | I508: ='По платам'!G510*$I$1 -> 4 | J508: ='По платам'!H510*$J$1 -> 0 | K508: ='По платам'!I510*$K$1 -> 4 | L508: ='По платам'!J510*$L$1 -> 5 | M508: ='По платам'!K510*$M$1 -> 0 | N508: ='По платам'!L510*'Состав прибора'!$B$16 -> 0
A509: Yageo | C509: CC0201KRX7R9BB221 | D509: =SUM(E509:N509) -> 2 | E509: ='По платам'!C511*$E$1 -> 0 | F509: ='По платам'!D511*$F$1 -> 0 | G509: ='По платам'!E511*$G$1 -> 0 | H509: ='По платам'!F511*$H$1 -> 0 | I509: ='По платам'!G511*$I$1 -> 0 | J509: ='По платам'!H511*$J$1 -> 0 | K509: ='По платам'!I511*$K$1 -> 2 | L509: ='По платам'!J511*$L$1 -> 0 | M509: ='По платам'!K511*$M$1 -> 0 | N509: ='По платам'!L511*'Состав прибора'!$B$16 -> 0
A510: Yageo | C510: CC0402FRNPO9BN300 | D510: =SUM(E510:N510) -> 2 | E510: ='По платам'!C512*$E$1 -> 0 | F510: ='По платам'!D512*$F$1 -> 0 | G510: ='По платам'!E512*$G$1 -> 0 | H510: ='По платам'!F512*$H$1 -> 0 | I510: ='По платам'!G512*$I$1 -> 0 | J510: ='По платам'!H512*$J$1 -> 0 | K510: ='По платам'!I512*$K$1 -> 0 | L510: ='По платам'!J512*$L$1 -> 2 | M510: ='По платам'!K512*$M$1 -> 0 | N510: ='По платам'!L512*'Состав прибора'!$B$16 -> 0
A511: Yageo | C511: CC0402FRNPO9BN360 | D511: =SUM(E511:N511) -> 1 | E511: ='По платам'!C513*$E$1 -> 0 | F511: ='По платам'!D513*$F$1 -> 0 | G511: ='По платам'!E513*$G$1 -> 0 | H511: ='По платам'!F513*$H$1 -> 0 | I511: ='По платам'!G513*$I$1 -> 0 | J511: ='По платам'!H513*$J$1 -> 0 | K511: ='По платам'!I513*$K$1 -> 1 | L511: ='По платам'!J513*$L$1 -> 0 | M511: ='По платам'!K513*$M$1 -> 0 | N511: ='По платам'!L513*'Состав прибора'!$B$16 -> 0
A512: Yageo | C512: CC0402GRNPO9BN151 | D512: =SUM(E512:N512) -> 1 | E512: ='По платам'!C514*$E$1 -> 0 | F512: ='По платам'!D514*$F$1 -> 0 | G512: ='По платам'!E514*$G$1 -> 0 | H512: ='По платам'!F514*$H$1 -> 0 | I512: ='По платам'!G514*$I$1 -> 0 | J512: ='По платам'!H514*$J$1 -> 0 | K512: ='По платам'!I514*$K$1 -> 1 | L512: ='По платам'!J514*$L$1 -> 0 | M512: ='По платам'!K514*$M$1 -> 0 | N512: ='По платам'!L514*'Состав прибора'!$B$16 -> 0
A513: Yageo | C513: CC0402GRNPO9BN271 | D513: =SUM(E513:N513) -> 1 | E513: ='По платам'!C515*$E$1 -> 0 | F513: ='По платам'!D515*$F$1 -> 0 | G513: ='По платам'!E515*$G$1 -> 0 | H513: ='По платам'!F515*$H$1 -> 0 | I513: ='По платам'!G515*$I$1 -> 0 | J513: ='По платам'!H515*$J$1 -> 0 | K513: ='По платам'!I515*$K$1 -> 1 | L513: ='По платам'!J515*$L$1 -> 0 | M513: ='По платам'!K515*$M$1 -> 0 | N513: ='По платам'!L515*'Состав прибора'!$B$16 -> 0
A514: Yageo | C514: CC0402GRNPO9BN391 | D514: =SUM(E514:N514) -> 2 | E514: ='По платам'!C516*$E$1 -> 0 | F514: ='По платам'!D516*$F$1 -> 0 | G514: ='По платам'!E516*$G$1 -> 0 | H514: ='По платам'!F516*$H$1 -> 0 | I514: ='По платам'!G516*$I$1 -> 0 | J514: ='По платам'!H516*$J$1 -> 0 | K514: ='По платам'!I516*$K$1 -> 2 | L514: ='По платам'!J516*$L$1 -> 0 | M514: ='По платам'!K516*$M$1 -> 0 | N514: ='По платам'!L516*'Состав прибора'!$B$16 -> 0
A515: Yageo | C515: CC0402JRNPO8BN330 | D515: =SUM(E515:N515) -> 1 | E515: ='По платам'!C517*$E$1 -> 0 | F515: ='По платам'!D517*$F$1 -> 0 | G515: ='По платам'!E517*$G$1 -> 0 | H515: ='По платам'!F517*$H$1 -> 0 | I515: ='По платам'!G517*$I$1 -> 0 | J515: ='По платам'!H517*$J$1 -> 0 | K515: ='По платам'!I517*$K$1 -> 1 | L515: ='По платам'!J517*$L$1 -> 0 | M515: ='По платам'!K517*$M$1 -> 0 | N515: ='По платам'!L517*'Состав прибора'!$B$16 -> 0
...

Sheet По платам
C1: C2B004CPU2 | D1: SBC_DIO_E1N004INF1 | E1: SBC_35_2C3_1_E1E001CPU1E | F1: PCIe104_PSU_E1N001PWR1 | G1: PCIe104_INF2_E1N006INF1 | H1: PCIe104_CON_E1N005INF1 | I1: EM-PCIE104-CPU_E1E001CPU1E | J1: PCIe104_INF_E1N001INF1 | K1: IB_2RS232_E1N002INF1 | L1: IB_2CAN_E1N003INF1
B2: Part Number
B3: ,TDK:MPZ0603S800HT000 | C3: =IFERROR(INDEX('C2B004CPU2'!N:N,MATCH('По платам'!$B3,'C2B004CPU2'!L:L,0)),0) -> 0 | D3: =IFERROR(INDEX(SBC_DIO_E1N004INF1!N:N,MATCH('По платам'!$B3,SBC_DIO_E1N004INF1!L:L,0)),0) -> 0 | E3: =IFERROR(INDEX(SBC_35_2C3_1_E1E001CPU1E!N:N,MATCH('По платам'!$B3,SBC_35_2C3_1_E1E001CPU1E!L:L,0)),0) -> 0 | F3: =IFERROR(INDEX(PCIe104_PSU_E1N001PWR1!N:N,MATCH('По платам'!$B3,PCIe104_PSU_E1N001PWR1!L:L,0)),0) -> 0 | G3: =IFERROR(INDEX(PCIe104_INF2_E1N006INF1!N:N,MATCH('По платам'!$B3,PCIe104_INF2_E1N006INF1!L:L,0)),0) -> 0 | H3: =IFERROR(INDEX(PCIe104_CON_E1N005INF1!N:N,MATCH('По платам'!$B3,PCIe104_CON_E1N005INF1!L:L,0)),0) -> 0 | I3: =IFERROR(INDEX('EM-PCIE104-CPU_E1E001CPU1E'!N:N,MATCH('По платам'!$B3,'EM-PCIE104-CPU_E1E001CPU1E'!L:L,0)),0) -> 0 | J3: =IFERROR(INDEX(PCIe104_INF_E1N001INF1!N:N,MATCH('По платам'!$B3,PCIe104_INF_E1N001INF1!L:L,0)),0) -> 0 | K3: =IFERROR(INDEX(IB_2RS232_E1N002INF1!N:N,MATCH('По платам'!$B3,IB_2RS232_E1N002INF1!L:L,0)),0) -> 0 | L3: =IFERROR(INDEX(IB_2CAN_E1N003INF1!N:N,MATCH('По платам'!$B3,IB_2CAN_E1N003INF1!L:L,0)),0) -> 0
B4: ,TDK:MPZ1005S900HT000 | C4: =IFERROR(INDEX('C2B004CPU2'!N:N,MATCH('По платам'!B4,'C2B004CPU2'!L:L,0)),0) -> 0 | D4: =IFERROR(INDEX(SBC_DIO_E1N004INF1!N:N,MATCH('По платам'!$B4,SBC_DIO_E1N004INF1!L:L,0)),0) -> 0 | E4: =IFERROR(INDEX(SBC_35_2C3_1_E1E001CPU1E!N:N,MATCH('По платам'!$B4,SBC_35_2C3_1_E1E001CPU1E!L:L,0)),0) -> 0 | F4: =IFERROR(INDEX(PCIe104_PSU_E1N001PWR1!N:N,MATCH('По платам'!$B4,PCIe104_PSU_E1N001PWR1!L:L,0)),0) -> 0 | G4: =IFERROR(INDEX(PCIe104_INF2_E1N006INF1!N:N,MATCH('По платам'!$B4,PCIe104_INF2_E1N006INF1!L:L,0)),0) -> 0 | H4: =IFERROR(INDEX(PCIe104_CON_E1N005INF1!N:N,MATCH('По платам'!$B4,PCIe104_CON_E1N005INF1!L:L,0)),0) -> 0 | I4: =IFERROR(INDEX('EM-PCIE104-CPU_E1E001CPU1E'!N:N,MATCH('По платам'!$B4,'EM-PCIE104-CPU_E1E001CPU1E'!L:L,0)),0) -> 0 | J4: =IFERROR(INDEX(PCIe104_INF_E1N001INF1!N:N,MATCH('По платам'!$B4,PCIe104_INF_E1N001INF1!L:L,0)),0) -> 0 | K4: =IFERROR(INDEX(IB_2RS232_E1N002INF1!N:N,MATCH('По платам'!$B4,IB_2RS232_E1N002INF1!L:L,0)),0) -> 0 | L4: =IFERROR(INDEX(IB_2CAN_E1N003INF1!N:N,MATCH('По платам'!$B4,IB_2CAN_E1N003INF1!L:L,0)),0) -> 0
B5: 3PEAK:TPT3232E-TS3R | C5: =IFERROR(INDEX('C2B004CPU2'!N:N,MATCH('По платам'!B5,'C2B004CPU2'!L:L,0)),0) -> 0 | D5: =IFERROR(INDEX(SBC_DIO_E1N004INF1!N:N,MATCH('По платам'!$B5,SBC_DIO_E1N004INF1!L:L,0)),0) -> 0 | E5: =IFERROR(INDEX(SBC_35_2C3_1_E1E001CPU1E!N:N,MATCH('По платам'!$B5,SBC_35_2C3_1_E1E001CPU1E!L:L,0)),0) -> 0 | F5: =IFERROR(INDEX(PCIe104_PSU_E1N001PWR1!N:N,MATCH('По платам'!$B5,PCIe104_PSU_E1N001PWR1!L:L,0)),0) -> 0 | G5: =IFERROR(INDEX(PCIe104_INF2_E1N006INF1!N:N,MATCH('По платам'!$B5,PCIe104_INF2_E1N006INF1!L:L,0)),0) -> 0 | H5: =IFERROR(INDEX(PCIe104_CON_E1N005INF1!N:N,MATCH('По платам'!$B5,PCIe104_CON_E1N005INF1!L:L,0)),0) -> 0 | I5: =IFERROR(INDEX('EM-PCIE104-CPU_E1E001CPU1E'!N:N,MATCH('По платам'!$B5,'EM-PCIE104-CPU_E1E001CPU1E'!L:L,0)),0) -> 0 | J5: =IFERROR(INDEX(PCIe104_INF_E1N001INF1!N:N,MATCH('По платам'!$B5,PCIe104_INF_E1N001INF1!L:L,0)),0) -> 0 | K5: =IFERROR(INDEX(IB_2RS232_E1N002INF1!N:N,MATCH('По платам'!$B5,IB_2RS232_E1N002INF1!L:L,0)),0) -> 1 | L5: =IFERROR(INDEX(IB_2CAN_E1N003INF1!N:N,MATCH('По платам'!$B5,IB_2CAN_E1N003INF1!L:L,0)),0) -> 0
B6: 3PEAK:TPT71042-SOAR | C6: =IFERROR(INDEX('C2B004CPU2'!N:N,MATCH('По платам'!B6,'C2B004CPU2'!L:L,0)),0) -> 0 | D6: =IFERROR(INDEX(SBC_DIO_E1N004INF1!N:N,MATCH('По платам'!$B6,SBC_DIO_E1N004INF1!L:L,0)),0) -> 0 | E6: =IFERROR(INDEX(SBC_35_2C3_1_E1E001CPU1E!N:N,MATCH('По платам'!$B6,SBC_35_2C3_1_E1E001CPU1E!L:L,0)),0) -> 0 | F6: =IFERROR(INDEX(PCIe104_PSU_E1N001PWR1!N:N,MATCH('По платам'!$B6,PCIe104_PSU_E1N001PWR1!L:L,0)),0) -> 0 | G6: =IFERROR(INDEX(PCIe104_INF2_E1N006INF1!N:N,MATCH('По платам'!$B6,PCIe104_INF2_E1N006INF1!L:L,0)),0) -> 0 | H6: =IFERROR(INDEX(PCIe104_CON_E1N005INF1!N:N,MATCH('По платам'!$B6,PCIe104_CON_E1N005INF1!L:L,0)),0) -> 0 | I6: =IFERROR(INDEX('EM-PCIE104-CPU_E1E001CPU1E'!N:N,MATCH('По платам'!$B6,'EM-PCIE104-CPU_E1E001CPU1E'!L:L,0)),0) -> 0 | J6: =IFERROR(INDEX(PCIe104_INF_E1N001INF1!N:N,MATCH('По платам'!$B6,PCIe104_INF_E1N001INF1!L:L,0)),0) -> 1 | K6: =IFERROR(INDEX(IB_2RS232_E1N002INF1!N:N,MATCH('По платам'!$B6,IB_2RS232_E1N002INF1!L:L,0)),0) -> 0 | L6: =IFERROR(INDEX(IB_2CAN_E1N003INF1!N:N,MATCH('По платам'!$B6,IB_2CAN_E1N003INF1!L:L,0)),0) -> 2
B7: 3PEAK:TPT7762-SSAR | C7: =IFERROR(INDEX('C2B004CPU2'!N:N,MATCH('По платам'!B7,'C2B004CPU2'!L:L,0)),0) -> 0 | D7: =IFERROR(INDEX(SBC_DIO_E1N004INF1!N:N,MATCH('По платам'!$B7,SBC_DIO_E1N004INF1!L:L,0)),0) -> 0 | E7: =IFERROR(INDEX(SBC_35_2C3_1_E1E001CPU1E!N:N,MATCH('По платам'!$B7,SBC_35_2C3_1_E1E001CPU1E!L:L,0)),0) -> 0 | F7: =IFERROR(INDEX(PCIe104_PSU_E1N001PWR1!N:N,MATCH('По платам'!$B7,PCIe104_PSU_E1N001PWR1!L:L,0)),0) -> 0 | G7: =IFERROR(INDEX(PCIe104_INF2_E1N006INF1!N:N,MATCH('По платам'!$B7,PCIe104_INF2_E1N006INF1!L:L,0)),0) -> 8 | H7: =IFERROR(INDEX(PCIe104_CON_E1N005INF1!N:N,MATCH('По платам'!$B7,PCIe104_CON_E1N005INF1!L:L,0)),0) -> 0 | I7: =IFERROR(INDEX('EM-PCIE104-CPU_E1E001CPU1E'!N:N,MATCH('По платам'!$B7,'EM-PCIE104-CPU_E1E001CPU1E'!L:L,0)),0) -> 0 | J7: =IFERROR(INDEX(PCIe104_INF_E1N001INF1!N:N,MATCH('По платам'!$B7,PCIe104_INF_E1N001INF1!L:L,0)),0) -> 4 | K7: =IFERROR(INDEX(IB_2RS232_E1N002INF1!N:N,MATCH('По платам'!$B7,IB_2RS232_E1N002INF1!L:L,0)),0) -> 5 | L7: =IFERROR(INDEX(IB_2CAN_E1N003INF1!N:N,MATCH('По платам'!$B7,IB_2CAN_E1N003INF1!L:L,0)),0) -> 0
B8: 3PEAK:TPV811S-4LTR | C8: =IFERROR(INDEX('C2B004CPU2'!N:N,MATCH('По платам'!B8,'C2B004CPU2'!L:L,0)),0) -> 0 | D8: =IFERROR(INDEX(SBC_DIO_E1N004INF1!N:N,MATCH('По платам'!$B8,SBC_DIO_E1N004INF1!L:L,0)),0) -> 0 | E8: =IFERROR(INDEX(SBC_35_2C3_1_E1E001CPU1E!N:N,MATCH('По платам'!$B8,SBC_35_2C3_1_E1E001CPU1E!L:L,0)),0) -> 1 | F8: =IFERROR(INDEX(PCIe104_PSU_E1N001PWR1!N:N,MATCH('По платам'!$B8,PCIe104_PSU_E1N001PWR1!L:L,0)),0) -> 0 | G8: =IFERROR(INDEX(PCIe104_INF2_E1N006INF1!N:N,MATCH('По платам'!$B8,PCIe104_INF2_E1N006INF1!L:L,0)),0) -> 0 | H8: =IFERROR(INDEX(PCIe104_CON_E1N005INF1!N:N,MATCH('По платам'!$B8,PCIe104_CON_E1N005INF1!L:L,0)),0) -> 0 | I8: =IFERROR(INDEX('EM-PCIE104-CPU_E1E001CPU1E'!N:N,MATCH('По платам'!$B8,'EM-PCIE104-CPU_E1E001CPU1E'!L:L,0)),0) -> 0 | J8: =IFERROR(INDEX(PCIe104_INF_E1N001INF1!N:N,MATCH('По платам'!$B8,PCIe104_INF_E1N001INF1!L:L,0)),0) -> 0 | K8: =IFERROR(INDEX(IB_2RS232_E1N002INF1!N:N,MATCH('По платам'!$B8,IB_2RS232_E1N002INF1!L:L,0)),0) -> 0 | L8: =IFERROR(INDEX(IB_2CAN_E1N003INF1!N:N,MATCH('По платам'!$B8,IB_2CAN_E1N003INF1!L:L,0)),0) -> 1
B9: Abracon Corporation:ABM11W-32.0000MHZ-8-D1X-T3 | C9: =IFERROR(INDEX('C2B004CPU2'!N:N,MATCH('По платам'!B9,'C2B004CPU2'!L:L,0)),0) -> 1 | D9: =IFERROR(INDEX(SBC_DIO_E1N004INF1!N:N,MATCH('По платам'!$B9,SBC_DIO_E1N004INF1!L:L,0)),0) -> 0 | E9: =IFERROR(INDEX(SBC_35_2C3_1_E1E001CPU1E!N:N,MATCH('По платам'!$B9,SBC_35_2C3_1_E1E001CPU1E!L:L,0)),0) -> 0 | F9: =IFERROR(INDEX(PCIe104_PSU_E1N001PWR1!N:N,MATCH('По платам'!$B9,PCIe104_PSU_E1N001PWR1!L:L,0)),0) -> 0 | G9: =IFERROR(INDEX(PCIe104_INF2_E1N006INF1!N:N,MATCH('По платам'!$B9,PCIe104_INF2_E1N006INF1!L:L,0)),0) -> 0 | H9: =IFERROR(INDEX(PCIe104_CON_E1N005INF1!N:N,MATCH('По платам'!$B9,PCIe104_CON_E1N005INF1!L:L,0)),0) -> 0 | I9: =IFERROR(INDEX('EM-PCIE104-CPU_E1E001CPU1E'!N:N,MATCH('По платам'!$B9,'EM-PCIE104-CPU_E1E001CPU1E'!L:L,0)),0) -> 0 | J9: =IFERROR(INDEX(PCIe104_INF_E1N001INF1!N:N,MATCH('По платам'!$B9,PCIe104_INF_E1N001INF1!L:L,0)),0) -> 0 | K9: =IFERROR(INDEX(IB_2RS232_E1N002INF1!N:N,MATCH('По платам'!$B9,IB_2RS232_E1N002INF1!L:L,0)),0) -> 0 | L9: =IFERROR(INDEX(IB_2CAN_E1N003INF1!N:N,MATCH('По платам'!$B9,IB_2CAN_E1N003INF1!L:L,0)),0) -> 0
B10: Abracon Corporation:ABM8-24.000MHZ-D1G-T | C10: =IFERROR(INDEX('C2B004CPU2'!N:N,MATCH('По платам'!B10,'C2B004CPU2'!L:L,0)),0) -> 0 | D10: =IFERROR(INDEX(SBC_DIO_E1N004INF1!N:N,MATCH('По платам'!$B10,SBC_DIO_E1N004INF1!L:L,0)),0) -> 0 | E10: =IFERROR(INDEX(SBC_35_2C3_1_E1E001CPU1E!N:N,MATCH('По платам'!$B10,SBC_35_2C3_1_E1E001CPU1E!L:L,0)),0) -> 0 | F10: =IFERROR(INDEX(PCIe104_PSU_E1N001PWR1!N:N,MATCH('По платам'!$B10,PCIe104_PSU_E1N001PWR1!L:L,0)),0) -> 0 | G10: =IFERROR(INDEX(PCIe104_INF2_E1N006INF1!N:N,MATCH('По платам'!$B10,PCIe104_INF2_E1N006INF1!L:L,0)),0) -> 0 | H10: =IFERROR(INDEX(PCIe104_CON_E1N005INF1!N:N,MATCH('По платам'!$B10,PCIe104_CON_E1N005INF1!L:L,0)),0) -> 0 | I10: =IFERROR(INDEX('EM-PCIE104-CPU_E1E001CPU1E'!N:N,MATCH('По платам'!$B10,'EM-PCIE104-CPU_E1E001CPU1E'!L:L,0)),0) -> 0 | J10: =IFERROR(INDEX(PCIe104_INF_E1N001INF1!N:N,MATCH('По платам'!$B10,PCIe104_INF_E1N001INF1!L:L,0)),0) -> 1 | K10: =IFERROR(INDEX(IB_2RS232_E1N002INF1!N:N,MATCH('По платам'!$B10,IB_2RS232_E1N002INF1!L:L,0)),0) -> 0 | L10: =IFERROR(INDEX(IB_2CAN_E1N003INF1!N:N,MATCH('По платам'!$B10,IB_2CAN_E1N003INF1!L:L,0)),0) -> 0
B11: Abracon Corporation:ABM8-25.000MHZ-12-D1X-T | C11: =IFERROR(INDEX('C2B004CPU2'!N:N,MATCH('По платам'!B11,'C2B004CPU2'!L:L,0)),0) -> 0 | D11: =IFERROR(INDEX(SBC_DIO_E1N004INF1!N:N,MATCH('По платам'!$B11,SBC_DIO_E1N004INF1!L:L,0)),0) -> 0 | E11: =IFERROR(INDEX(SBC_35_2C3_1_E1E001CPU1E!N:N,MATCH('По платам'!$B11,SBC_35_2C3_1_E1E001CPU1E!L:L,0)),0) -> 5 | F11: =IFERROR(INDEX(PCIe104_PSU_E1N001PWR1!N:N,MATCH('По платам'!$B11,PCIe104_PSU_E1N001PWR1!L:L,0)),0) -> 0 | G11: =IFERROR(INDEX(PCIe104_INF2_E1N006INF1!N:N,MATCH('По платам'!$B11,PCIe104_INF2_E1N006INF1!L:L,0)),0) -> 0 | H11: =IFERROR(INDEX(PCIe104_CON_E1N005INF1!N:N,MATCH('По платам'!$B11,PCIe104_CON_E1N005INF1!L:L,0)),0) -> 0 | I11: =IFERROR(INDEX('EM-PCIE104-CPU_E1E001CPU1E'!N:N,MATCH('По платам'!$B11,'EM-PCIE104-CPU_E1E001CPU1E'!L:L,0)),0) -> 3 | J11: =IFERROR(INDEX(PCIe104_INF_E1N001INF1!N:N,MATCH('По платам'!$B11,PCIe104_INF_E1N001INF1!L:L,0)),0) -> 5 | K11: =IFERROR(INDEX(IB_2RS232_E1N002INF1!N:N,MATCH('По платам'!$B11,IB_2RS232_E1N002INF1!L:L,0)),0) -> 0 | L11: =IFERROR(INDEX(IB_2CAN_E1N003INF1!N:N,MATCH('По платам'!$B11,IB_2CAN_E1N003INF1!L:L,0)),0) -> 0
B12: Abracon Corporation:ABM8W-12.0000MHZ-8-D1X-T3 | C12: =IFERROR(INDEX('C2B004CPU2'!N:N,MATCH('По платам'!B12,'C2B004CPU2'!L:L,0)),0) -> 0 | D12: =IFERROR(INDEX(SBC_DIO_E1N004INF1!N:N,MATCH('По платам'!$B12,SBC_DIO_E1N004INF1!L:L,0)),0) -> 0 | E12: =IFERROR(INDEX(SBC_35_2C3_1_E1E001CPU1E!N:N,MATCH('По платам'!$B12,SBC_35_2C3_1_E1E001CPU1E!L:L,0)),0) -> 1 | F12: =IFERROR(INDEX(PCIe104_PSU_E1N001PWR1!N:N,MATCH('По платам'!$B12,PCIe104_PSU_E1N001PWR1!L:L,0)),0) -> 0 | G12: =IFERROR(INDEX(PCIe104_INF2_E1N006INF1!N:N,MATCH('По платам'!$B12,PCIe104_INF2_E1N006INF1!L:L,0)),0) -> 2 | H12: =IFERROR(INDEX(PCIe104_CON_E1N005INF1!N:N,MATCH('По платам'!$B12,PCIe104_CON_E1N005INF1!L:L,0)),0) -> 0 | I12: =IFERROR(INDEX('EM-PCIE104-CPU_E1E001CPU1E'!N:N,MATCH('По платам'!$B12,'EM-PCIE104-CPU_E1E001CPU1E'!L:L,0)),0) -> 1 | J12: =IFERROR(INDEX(PCIe104_INF_E1N001INF1!N:N,MATCH('По платам'!$B12,PCIe104_INF_E1N001INF1!L:L,0)),0) -> 2 | K12: =IFERROR(INDEX(IB_2RS232_E1N002INF1!N:N,MATCH('По платам'!$B12,IB_2RS232_E1N002INF1!L:L,0)),0) -> 1 | L12: =IFERROR(INDEX(IB_2CAN_E1N003INF1!N:N,MATCH('По платам'!$B12,IB_2CAN_E1N003INF1!L:L,0)),0) -> 1
B13: Abracon Corporation:ASDMB-14.31818MHZ-LY-T | C13: =IFERROR(INDEX('C2B004CPU2'!N:N,MATCH('По платам'!B13,'C2B004CPU2'!L:L,0)),0) -> 0 | D13: =IFERROR(INDEX(SBC_DIO_E1N004INF1!N:N,MATCH('По платам'!$B13,SBC_DIO_E1N004INF1!L:L,0)),0) -> 0 | E13: =IFERROR(INDEX(SBC_35_2C3_1_E1E001CPU1E!N:N,MATCH('По платам'!$B13,SBC_35_2C3_1_E1E001CPU1E!L:L,0)),0) -> 1 | F13: =IFERROR(INDEX(PCIe104_PSU_E1N001PWR1!N:N,MATCH('По платам'!$B13,PCIe104_PSU_E1N001PWR1!L:L,0)),0) -> 0 | G13: =IFERROR(INDEX(PCIe104_INF2_E1N006INF1!N:N,MATCH('По платам'!$B13,PCIe104_INF2_E1N006INF1!L:L,0)),0) -> 0 | H13: =IFERROR(INDEX(PCIe104_CON_E1N005INF1!N:N,MATCH('По платам'!$B13,PCIe104_CON_E1N005INF1!L:L,0)),0) -> 0 | I13: =IFERROR(INDEX('EM-PCIE104-CPU_E1E001CPU1E'!N:N,MATCH('По платам'!$B13,'EM-PCIE104-CPU_E1E001CPU1E'!L:L,0)),0) -> 1 | J13: =IFERROR(INDEX(PCIe104_INF_E1N001INF1!N:N,MATCH('По платам'!$B13,PCIe104_INF_E1N001INF1!L:L,0)),0) -> 0 | K13: =IFERROR(INDEX(IB_2RS232_E1N002INF1!N:N,MATCH('По платам'!$B13,IB_2RS232_E1N002INF1!L:L,0)),0) -> 0 | L13: =IFERROR(INDEX(IB_2CAN_E1N003INF1!N:N,MATCH('По платам'!$B13,IB_2CAN_E1N003INF1!L:L,0)),0) -> 0
B14: Abracon Corporation:AX3DCF1-156.2500 | C14: =IFERROR(INDEX('C2B004CPU2'!N:N,MATCH('По платам'!B14,'C2B004CPU2'!L:L,0)),0) -> 0 | D14: =IFERROR(INDEX(SBC_DIO_E1N004INF1!N:N,MATCH('По платам'!$B14,SBC_DIO_E1N004INF1!L:L,0)),0) -> 0 | E14: =IFERROR(INDEX(SBC_35_2C3_1_E1E001CPU1E!N:N,MATCH('По платам'!$B14,SBC_35_2C3_1_E1E001CPU1E!L:L,0)),0) -> 1 | F14: =IFERROR(INDEX(PCIe104_PSU_E1N001PWR1!N:N,MATCH('По платам'!$B14,PCIe104_PSU_E1N001PWR1!L:L,0)),0) -> 0 | G14: =IFERROR(INDEX(PCIe104_INF2_E1N006INF1!N:N,MATCH('По платам'!$B14,PCIe104_INF2_E1N006INF1!L:L,0)),0) -> 0 | H14: =IFERROR(INDEX(PCIe104_CON_E1N005INF1!N:N,MATCH('По платам'!$B14,PCIe104_CON_E1N005INF1!L:L,0)),0) -> 0 | I14: =IFERROR(INDEX('EM-PCIE104-CPU_E1E001CPU1E'!N:N,MATCH('По платам'!$B14,'EM-PCIE104-CPU_E1E001CPU1E'!L:L,0)),0) -> 1 | J14: =IFERROR(INDEX(PCIe104_INF_E1N001INF1!N:N,MATCH('По платам'!$B14,PCIe104_INF_E1N001INF1!L:L,0)),0) -> 0 | K14: =IFERROR(INDEX(IB_2RS232_E1N002INF1!N:N,MATCH('По платам'!$B14,IB_2RS232_E1N002INF1!L:L,0)),0) -> 0 | L14: =IFERROR(INDEX(IB_2CAN_E1N003INF1!N:N,MATCH('По платам'!$B14,IB_2CAN_E1N003INF1!L:L,0)),0) -> 0
B15: Adam Tech:LHA-02-TS | C15: =IFERROR(INDEX('C2B004CPU2'!N:N,MATCH('По платам'!B15,'C2B004CPU2'!L:L,0)),0) -> 1 | D15: =IFERROR(INDEX(SBC_DIO_E1N004INF1!N:N,MATCH('По платам'!$B15,SBC_DIO_E1N004INF1!L:L,0)),0) -> 0 | E15: =IFERROR(INDEX(SBC_35_2C3_1_E1E001CPU1E!N:N,MATCH('По платам'!$B15,SBC_35_2C3_1_E1E001CPU1E!L:L,0)),0) -> 0 | F15: =IFERROR(INDEX(PCIe104_PSU_E1N001PWR1!N:N,MATCH('По платам'!$B15,PCIe104_PSU_E1N001PWR1!L:L,0)),0) -> 0 | G15: =IFERROR(INDEX(PCIe104_INF2_E1N006INF1!N:N,MATCH('По платам'!$B15,PCIe104_INF2_E1N006INF1!L:L,0)),0) -> 0 | H15: =IFERROR(INDEX(PCIe104_CON_E1N005INF1!N:N,MATCH('По платам'!$B15,PCIe104_CON_E1N005INF1!L:L,0)),0) -> 0 | I15: =IFERROR(INDEX('EM-PCIE104-CPU_E1E001CPU1E'!N:N,MATCH('По платам'!$B15,'EM-PCIE104-CPU_E1E001CPU1E'!L:L,0)),0) -> 0 | J15: =IFERROR(INDEX(PCIe104_INF_E1N001INF1!N:N,MATCH('По платам'!$B15,PCIe104_INF_E1N001INF1!L:L,0)),0) -> 0 | K15: =IFERROR(INDEX(IB_2RS232_E1N002INF1!N:N,MATCH('По платам'!$B15,IB_2RS232_E1N002INF1!L:L,0)),0) -> 0 | L15: =IFERROR(INDEX(IB_2CAN_E1N003INF1!N:N,MATCH('По платам'!$B15,IB_2CAN_E1N003INF1!L:L,0)),0) -> 0
... B637: (пусто) | C637: =IFERROR(INDEX('C2B004CPU2'!N:N,MATCH('По платам'!B637,'C2B004CPU2'!L:L,0)),0) -> 0 | D637: =IFERROR(INDEX(SBC_DIO_E1N004INF1!N:N,MATCH('По платам'!$B637,SBC_DIO_E1N004INF1!L:L,0)),0) -> 0 | E637: =IFERROR(INDEX(SBC_35_2C3_1_E1E001CPU1E!N:N,MATCH('По платам'!$B637,SBC_35_2C3_1_E1E001CPU1E!L:L,0)),0) -> 0 | F637: =IFERROR(INDEX(PCIe104_PSU_E1N001PWR1!N:N,MATCH('По платам'!$B637,PCIe104_PSU_E1N001PWR1!L:L,0)),0) -> 0 | G637: =IFERROR(INDEX(PCIe104_INF2_E1N006INF1!N:N,MATCH('По платам'!$B637,PCIe104_INF2_E1N006INF1!L:L,0)),0) -> 0 | H637: =IFERROR(INDEX(PCIe104_CON_E1N005INF1!N:N,MATCH('По платам'!$B637,PCIe104_CON_E1N005INF1!L:L,0)),0) -> 0 | I637: =IFERROR(INDEX('EM-PCIE104-CPU_E1E001CPU1E'!N:N,MATCH('По платам'!$B637,'EM-PCIE104-CPU_E1E001CPU1E'!L:L,0)),0) -> 0 | J637: =IFERROR(INDEX(PCIe104_INF_E1N001INF1!N:N,MATCH('По платам'!$B637,PCIe104_INF_E1N001INF1!L:L,0)),0) -> 0 | K637: =IFERROR(INDEX(IB_2RS232_E1N002INF1!N:N,MATCH('По платам'!$B637,IB_2RS232_E1N002INF1!L:L,0)),0) -> 0 | L637: =IFERROR(INDEX(IB_2CAN_E1N003INF1!N:N,MATCH('По платам'!$B637,IB_2CAN_E1N003INF1!L:L,0)),0) -> 0

Sheet IB_2CAN_E1N003INF1
A1: ID | B1: Date | C1: N | D1: Type | E1: File | F1: Count | G1: # | H1: Analog | I1: Description | J1: Manufacturer part number | K1: Mfg name | L1: Mfg part number | M1: Part number | N1: Qty | O1: Ref designator | P1: Qty2
A2: IB_2CAN_E1N003INF1 | B2: Thursday, March 21, 2024 | C2: 3 | D2: PanelPC | E2: IB_2CAN_E1N003INF1.xlsx | F2: 1 | G2: 1 | I2: CRYSTAL 12.0000MHZ 8PF SMD | J2: ABM8W-12.0000MHZ-8-D1X-T3 | K2: Abracon Corporation | L2: Abracon Corporation:ABM8W-12.0000MHZ-8-D1X-T3 | M2: 10191 | N2: 1 | O2: BQ1 | P2: 1
A3: IB_2CAN_E1N003INF1 | B3: Thursday, March 21, 2024 | C3: 3 | D3: PanelPC | E3: IB_2CAN_E1N003INF1.xlsx | F3: 1 | G3: 2 | I3: CAP CER 0603 16V 10uF X6S +/-20% | J3: CL10X106MO8NRN | K3: Samsung | L3: Samsung:CL10X106MO8NRN | M3: 42431 | N3: 14 | O3: C1,C3,C15,C21,C25,C29,C31,C32,C33,C39,C41,C42,C43,C46 | P3: 14
A4: IB_2CAN_E1N003INF1 | B4: Thursday, March 21, 2024 | C4: 3 | D4: PanelPC | E4: IB_2CAN_E1N003INF1.xlsx | F4: 1 | G4: 3 | I4: CAP CERAMIC, 0402, 0.1uF, 50V, X7R, +/-10% | J4: CL05B104KB54PNC | K4: Samsung | L4: Samsung:CL05B104KB54PNC | M4: 2054 | N4: 20 | O4: C2,C4,C6,C7,C8,C9,C10,C11,C14,C18,C19,C20,C22,C23,C26,C27,C34,C36,C37,C44 | P4: 20
A5: IB_2CAN_E1N003INF1 | B5: Thursday, March 21, 2024 | C5: 3 | D5: PanelPC | E5: IB_2CAN_E1N003INF1.xlsx | F5: 1 | G5: 4 | I5: CAP CER 0805 16 V 22 uF X6S В±20% | J5: CL21X226MOYNNWE | K5: Samsung | L5: Samsung:CL21X226MOYNNWE | M5: 42374 | N5: 1 | O5: C5 | P5: 1
A6: IB_2CAN_E1N003INF1 | B6: Thursday, March 21, 2024 | C6: 3 | D6: PanelPC | E6: IB_2CAN_E1N003INF1.xlsx | F6: 1 | G6: 5 | I6: CAP CER 0402 16V 2.2uF X6S +/-10% | J6: C1005X6S1C225K050BC | K6: TDK | L6: TDK:C1005X6S1C225K050BC | M6: 42476 | N6: 3 | O6: C12,C30,C40 | P6: 3
A7: IB_2CAN_E1N003INF1 | B7: Thursday, March 21, 2024 | C7: 3 | D7: PanelPC | E7: IB_2CAN_E1N003INF1.xlsx | F7: 1 | G7: 6 | I7: CAP CERAMIC, 0402, 0.01uF, 50V, X7R, +/-10% | J7: CL05B103KB5NNNC | K7: Samsung | L7: Samsung:CL05B103KB5NNNC | M7: 4320 | N7: 1 | O7: C13 | P7: 1
A8: IB_2CAN_E1N003INF1 | B8: Thursday, March 21, 2024 | C8: 3 | D8: PanelPC | E8: IB_2CAN_E1N003INF1.xlsx | F8: 1 | G8: 7 | I8: CAP CER, 0402, 10pF, 50V, C0G, +/-5% | J8: CL05C100JB5NNNC | K8: Samsung | L8: Samsung:CL05C100JB5NNNC | M8: 33765 | N8: 2 | O8: C16,C17 | P8: 2
A9: IB_2CAN_E1N003INF1 | B9: Thursday, March 21, 2024 | C9: 3 | D9: PanelPC | E9: IB_2CAN_E1N003INF1.xlsx | F9: 1 | G9: 8 | I9: CAP CER 0603 16 V 10 uF X5R В±10% | J9: CL10A106KO8NQNC | K9: Samsung | L9: Samsung:CL10A106KO8NQNC | M9: 42379 | N9: 1 | O9: C24 | P9: 1
A10: IB_2CAN_E1N003INF1 | B10: Thursday, March 21, 2024 | C10: 3 | D10: PanelPC | E10: IB_2CAN_E1N003INF1.xlsx | F10: 1 | G10: 9 | I10: CAP CER, 0603, 0.1uF, 100V, X7R, +/-10% | J10: CL10B104KC8NNNC | K10: Samsung | L10: Samsung:CL10B104KC8NNNC | M10: 33769 | N10: 2 | O10: C28,C38 | P10: 2
A11: IB_2CAN_E1N003INF1 | B11: Thursday, March 21, 2024 | C11: 3 | D11: PanelPC | E11: IB_2CAN_E1N003INF1.xlsx | F11: 1 | G11: 10 | I11: CAP CER 1206, 1000pF, В±10%, 2000V, X7R | J11: CC1206KKX7RDBB102 | K11: Yageo | L11: Yageo:CC1206KKX7RDBB102 | M11: 10481 | N11: 2 | O11: C35,C45 | P11: 2
A12: IB_2CAN_E1N003INF1 | B12: Thursday, March 21, 2024 | C12: 3 | D12: PanelPC | E12: IB_2CAN_E1N003INF1.xlsx | F12: 1 | G12: 11 | I12: CAP CER, 0402, 100pF, 50V, C0G, +/-5% | J12: CL05C101JB5NNNC | K12: Samsung | L12: Samsung:CL05C101JB5NNNC | M12: 42335 | N12: 4 | O12: C47,C48,C49,C50 | P12: 4
A13: IB_2CAN_E1N003INF1 | B13: Thursday, March 21, 2024 | C13: 3 | D13: PanelPC | E13: IB_2CAN_E1N003INF1.xlsx | F13: 1 | G13: 12 | I13: CAP CERAMIC, 0402, 1000pF, 50V, X7R, +/-5% | J13: CL05B102JB5NNNC | K13: Samsung | L13: Samsung:CL05B102JB5NNNC | M13: 1168 | N13: 1 | O13: C51 | P13: 1
... A20: IB_2CAN_E1N003INF1 | B20: Thursday, March 21, 2024 | C20: 3 | D20: PanelPC | E20: IB_2CAN_E1N003INF1.xlsx | F20: 1 | G20: 19 | I20: IC DC-DC CONVERTER 5V 1W | J20: B0505S-1WR3 | K20: Mornsun | L20: Mornsun:B0505S-1WR3 | M20: 10163 | N20: 2 | O20: D7,D10 | P20: 2
A21: IB_2CAN_E1N003INF1 | B21: Thursday, March 21, 2024 | C21: 3 | D21: PanelPC | E21: IB_2CAN_E1N003INF1.xlsx | F21: 1 | G21: 20 | I21: IND, 0402, 90ohms, 2,3 A, DCR 38 mOhm | J21: MPZ1005S900HT000 | M21: 10522 | N21: 4 | O21: L1,L3,L6,L9 | P21: 4
A22: IB_2CAN_E1N003INF1 | B22: Thursday, March 21, 2024 | C22: 3 | D22: PanelPC | E22: IB_2CAN_E1N003INF1.xlsx | F22: 1 | G22: 21 | I22: 90 Om 300mA, 2LN, Common mode choke coil | J22: SDCW1608S-2-900TF | K22: Sunlord | L22: Sunlord:SDCW1608S-2-900TF | M22: 10355 | N22: 1 | O22: L2 | P22: 1
A23: IB_2CAN_E1N003INF1 | B23: Thursday, March 21, 2024 | C23: 3 | D23: PanelPC | E23: IB_2CAN_E1N003INF1.xlsx | F23: 1 | G23: 22 | I23: 300 Ohm 400mA, Common mode choke coil | J23: SDCW2520S-2-301TF | K23: Sunlord | L23: Sunlord:SDCW2520S-2-301TF | M23: 10354 | N23: 2 | O23: L4,L7 | P23: 2
A24: IB_2CAN_E1N003INF1 | B24: Thursday, March 21, 2024 | C24: 3 | D24: PanelPC | E24: IB_2CAN_E1N003INF1.xlsx | F24: 1 | G24: 23 | I24: FIXED IND 10UH 770MA 345MOHM SMD | J24: SWPA4012S100MT | K24: Sunlord | L24: Sunlord:SWPA4012S100MT | M24: 10416 | N24: 2 | O24: L5,L8 | P24: 2
A25: IB_2CAN_E1N003INF1 | B25: Thursday, March 21, 2024 | C25: 3 | D25: PanelPC | E25: IB_2CAN_E1N003INF1.xlsx | F25: 1 | G25: 24 | I25: Test Points, 1mm DIA | M25: 10295 | N25: 8 | O25: P1,P2,P10,P11,P16,P17,P18,P19 | P25: 8
A26: IB_2CAN_E1N003INF1 | B26: Thursday, March 21, 2024 | C26: 3 | D26: PanelPC | E26: IB_2CAN_E1N003INF1.xlsx | F26: 1 | G26: 25 | I26: Test point Ostec Bed of Nails | M26: 310 | N26: 7 | O26: P3,P12,P13,P14,P15,P20,P21 | P26: 7
A27: IB_2CAN_E1N003INF1 | B27: Thursday, March 21, 2024 | C27: 3 | D27: PanelPC | E27: IB_2CAN_E1N003INF1.xlsx | F27: 1 | G27: 26 | I27: RES SMD 1kohm +/-1% 1/16W 0402 | J27: RC0402FR-071KL | K27: Yageo | L27: Yageo:RC0402FR-071KL | M27: 39677 | N27: 4 | O27: R1,R2,R3,R4 | P27: 4
A28: IB_2CAN_E1N003INF1 | B28: Thursday, March 21, 2024 | C28: 3 | D28: PanelPC | E28: IB_2CAN_E1N003INF1.xlsx | F28: 1 | G28: 27 | I28: RES SMD 4.7kohm +/-1% 1/16W 0402 | J28: RC0402FR-074K7L | K28: Yageo | L28: Yageo:RC0402FR-074K7L | M28: 40058 | N28: 6 | O28: R5,R8,R9,R13,R14,R17 | P28: 6
A29: IB_2CAN_E1N003INF1 | B29: Thursday, March 21, 2024 | C29: 3 | D29: PanelPC | E29: IB_2CAN_E1N003INF1.xlsx | F29: 1 | G29: 28 | I29: RES SMD 1.3kohm +/-1% 1/16W 0402 | J29: RC0402FR-071K3L | K29: Yageo | L29: Yageo:RC0402FR-071K3L | M29: 39659 | N29: 1 | O29: R6 | P29: 1
A30: IB_2CAN_E1N003INF1 | B30: Thursday, March 21, 2024 | C30: 3 | D30: PanelPC | E30: IB_2CAN_E1N003INF1.xlsx | F30: 1 | G30: 29 | I30: RES SMD 0ohm +/-5% 1/16W 0402 | J30: AC0402JR-070RL | K30: Yageo | L30: Yageo:AC0402JR-070RL | M30: 16369 | N30: 2 | O30: R7,R19 | P30: 2
A31: IB_2CAN_E1N003INF1 | B31: Thursday, March 21, 2024 | C31: 3 | D31: PanelPC | E31: IB_2CAN_E1N003INF1.xlsx | F31: 1 | G31: 30 | I31: RES SMD 0ohm +/-5% 1/16W 0402 | J31: AC0402JR-070RL | K31: Yageo | L31: Yageo:AC0402JR-070RL | M31: 16369 | N31: 1 | O31: R10 | P31: 1
A32: IB_2CAN_E1N003INF1 | B32: Thursday, March 21, 2024 | C32: 3 | D32: PanelPC | E32: IB_2CAN_E1N003INF1.xlsx | F32: 1 | G32: 31 | I32: RES SMD 100kohm +/-5% 1/16W 0402 | J32: RC0402JR-07100KL | K32: Yageo | L32: Yageo:RC0402JR-07100KL | M32: 40583 | N32: 4 | O32: R11,R23,R26,R32 | P32: 4
A33: IB_2CAN_E1N003INF1 | B33: Thursday, March 21, 2024 | C33: 3 | D33: PanelPC | E33: IB_2CAN_E1N003INF1.xlsx | F33: 1 | G33: 32 | I33: RES SMD 1Mohm +/-5% 1/4W 1206 | J33: AC1206JR-071ML | K33: Yageo | L33: Yageo:AC1206JR-071ML | M33: 26159 | N33: 2 | O33: R12,R15 | P33: 2
A34: IB_2CAN_E1N003INF1 | B34: Thursday, March 21, 2024 | C34: 3 | D34: PanelPC | E34: IB_2CAN_E1N003INF1.xlsx | F34: 1 | G34: 33 | I34: RES SMD 62ohm +/-1% 1/16W 0402 | J34: RC0402FR-0762RL | K34: Yageo | L34: Yageo:RC0402FR-0762RL | M34: 40160 | N34: 4 | O34: R21,R22,R27,R28 | P34: 4
A35: IB_2CAN_E1N003INF1 | B35: Thursday, March 21, 2024 | C35: 3 | D35: PanelPC | E35: IB_2CAN_E1N003INF1.xlsx | F35: 1 | G35: 34 | I35: RES , 0402, 10kohms, 1%, 1/16W | J35: CR0402-FX-1002-G | K35: Bourns | L35: Bourns:CR0402-FX-1002-G | M35: 2554 | N35: 3 | O35: R24,R30,R33 | P35: 3
A36: IB_2CAN_E1N003INF1 | B36: Thursday, March 21, 2024 | C36: 3 | D36: PanelPC | E36: IB_2CAN_E1N003INF1.xlsx | F36: 1 | G36: 35 | I36: RES SMD 270ohm +/-1% 1/2W 1210 | J36: AC1210FR-07270RL | K36: Yageo | L36: Yageo:AC1210FR-07270RL | M36: 27546 | N36: 2 | O36: R25,R31 | P36: 2
A37: IB_2CAN_E1N003INF1 | B37: Thursday, March 21, 2024 | C37: 3 | D37: PanelPC | E37: IB_2CAN_E1N003INF1.xlsx | F37: 1 | G37: 36 | I37: LED 2V 20mA YELLOW COLOR SMD 1.0x0.5 mm | J37: APHHS1005SYCK | K37: Kingbright | L37: Kingbright:APHHS1005SYCK | M37: 1266 | N37: 2 | O37: VD1,VD3 | P37: 2
A38: IB_2CAN_E1N003INF1 | B38: Thursday, March 21, 2024 | C38: 3 | D38: PanelPC | E38: IB_2CAN_E1N003INF1.xlsx | F38: 1 | G38: 37 | I38: LED 2.1V 20mA GREEN COLOR SMD 1.0x0.5 mm | J38: APHHS1005CGCK | K38: Kingbright | L38: Kingbright:APHHS1005CGCK | M38: 5636 | N38: 2 | O38: VD2,VD4 | P38: 2
... A45: IB_2CAN_E1N003INF1 | B45: Thursday, March 21, 2024 | C45: 3 | D45: PanelPC | E45: IB_2CAN_E1N003INF1.xlsx | F45: 1 | G45: 44 | I45: CONN SH 1.0mm WAFER SMT TOP ENTRY TYPE | J45: W9110-20PCSWXDR | K45: Hsuan Mao | L45: Hsuan Mao:W9110-20PCSWXDR | M45: 10437 | N45: 1 | O45: X3 | P45: 1
N46: =SUM(N2:N45) -> 132 | P46: =SUM(P2:P45) -> 132

Sheet IB_2RS232_E1N002INF1
A1: ID | B1: Date | C1: N | D1: Type | E1: File | F1: Count | G1: # | H1: Analog | I1: Description | J1: Manufacturer part number | K1: Mfg name | L1: Mfg part number | M1: Part number | N1: Qty | O1: Ref designator
A2: IB_2RS232_E1N002INF1 | B2: Thursday, March 21, 2024 | C2: 1 | D2: IndustrialPC | E2: IB_2RS232_E1N002INF1_BOM.xlsx | F2: 2 | G2: 1 | I2: CRYSTAL 12.0000MHZ 8PF SMD | J2: ABM8W-12.0000MHZ-8-D1X-T3 | K2: Abracon Corporation | L2: Abracon Corporation:ABM8W-12.0000MHZ-8-D1X-T3 | M2: 10191 | N2: 1 | O2: BQ1
A3: IB_2RS232_E1N002INF1 | B3: Thursday, March 21, 2024 | C3: 1 | D3: IndustrialPC | E3: IB_2RS232_E1N002INF1_BOM.xlsx | F3: 2 | G3: 2 | I3: CAP CER 0402 16V 2.2uF X6S +/-10% | J3: C1005X6S1C225K050BC | K3: TDK | L3: TDK:C1005X6S1C225K050BC | M3: 42476 | N3: 11 | O3: C1, C5, C27, C39, C48, C56, C67, C78, C89, C90, C91, C92, C93
A4: IB_2RS232_E1N002INF1 | B4: Thursday, March 21, 2024 | C4: 1 | D4: IndustrialPC | E4: IB_2RS232_E1N002INF1_BOM.xlsx | F4: 2 | G4: 3 | I4: CAP CER, 220nF, +/-10%, 16V, X7R, 0402 | J4: CL05B224KO5NNNC | K4: Samsung | L4: Samsung:CL05B224KO5NNNC | M4: 33885 | N4: 22 | O4: C2, C9, C10, C11, C13, C14, C18, C30, C31, C54, C59, C60, C61, C62, C70, C71, C72, C73, C80, C81, C82, C85
A5: IB_2RS232_E1N002INF1 | B5: Thursday, March 21, 2024 | C5: 1 | D5: IndustrialPC | E5: IB_2RS232_E1N002INF1_BOM.xlsx | F5: 2 | G5: 4 | I5: CAP CERAMIC, 0402, 0.1uF, 50V, X7R, +/-10% | J5: CL05B104KB54PNC | K5: Samsung | L5: Samsung:CL05B104KB54PNC | M5: 2054 | N5: 27 | O5: C3, C4, C7, C8, C15, C16, C19, C20, C21, C24, C25, C28, C29, C32, C33, C35, C40, C42, C43, C44, C49, C55, C57, C58, C68, C69, C79
A6: IB_2RS232_E1N002INF1 | B6: Thursday, March 21, 2024 | C6: 1 | D6: IndustrialPC | E6: IB_2RS232_E1N002INF1_BOM.xlsx | F6: 2 | G6: 5 | I6: CAP CERAMIC, 0603, 10uF, 16V, X6S, +/-20% | J6: GRM188C81C106MA73 | K6: Murata | L6: Murata:GRM188C81C106MA73 | M6: 1256 | N6: 15 | O6: C6, C12, C17, C26, C34, C36, C37, C38, C41, C45, C46, C47, C51, C52, C53
A7: IB_2RS232_E1N002INF1 | B7: Thursday, March 21, 2024 | C7: 1 | D7: IndustrialPC | E7: IB_2RS232_E1N002INF1_BOM.xlsx | F7: 2 | G7: 6 | I7: CAP CER, 0402, 10pF, 50V, C0G, +/-5% | J7: CL05C100JB5NNNC | K7: Samsung | L7: Samsung:CL05C100JB5NNNC | M7: 33765 | N7: 2 | O7: C22, C23
A8: IB_2RS232_E1N002INF1 | B8: Thursday, March 21, 2024 | C8: 1 | D8: IndustrialPC | E8: IB_2RS232_E1N002INF1_BOM.xlsx | F8: 2 | G8: 7 | I8: CAP CER 0402 10uF 10V X5R +/-20% | J8: CL05A106MP6NUN8 | K8: Samsung | L8: Samsung:CL05A106MP6NUN8 | M8: 3995 | N8: 1 | O8: C50
A9: IB_2RS232_E1N002INF1 | B9: Thursday, March 21, 2024 | C9: 1 | D9: IndustrialPC | E9: IB_2RS232_E1N002INF1_BOM.xlsx | F9: 2 | G9: 8 | I9: CAP CER, 0402, 100pF, 50V, C0G, +/-5% | J9: CL05C101JB5NNNC | K9: Samsung | L9: Samsung:CL05C101JB5NNNC | M9: 42335 | N9: 8 | O9: C63, C64, C65, C66, C74, C75, C76, C77
A10: IB_2RS232_E1N002INF1 | B10: Thursday, March 21, 2024 | C10: 1 | D10: IndustrialPC | E10: IB_2RS232_E1N002INF1_BOM.xlsx | F10: 2 | G10: 9 | I10: CAP CER 1206, 1000pF, Д…10%, 2000V, X7R | J10: CC1206KKX7RDBB102 | K10: Yageo | L10: Yageo:CC1206KKX7RDBB102 | M10: 10481 | N10: 3 | O10: C86, C87, C88
A11: IB_2RS232_E1N002INF1 | B11: Thursday, March 21, 2024 | C11: 1 | D11: IndustrialPC | E11: IB_2RS232_E1N002INF1_BOM.xlsx | F11: 2 | G11: 10 | I11: USB 2.0 PORT & DUAL UART PORTS 64-TQFP | J11: F81532U | K11: Fintek | L11: Fintek:F81532U | M11: 1482 | N11: 1 | O11: D1
A12: IB_2RS232_E1N002INF1 | B12: Thursday, March 21, 2024 | C12: 1 | D12: IndustrialPC | E12: IB_2RS232_E1N002INF1_BOM.xlsx | F12: 2 | G12: 11 | I12: SINGLE 3.3/5V RS232/RS422/RS485 MULTIPROTOCOL TRANSCEIVER 40-TQFN | J12: F81439AN | K12: Fintek | L12: Fintek:F81439AN | M12: 1505 | N12: 2 | O12: D2, D3
A13: IB_2RS232_E1N002INF1 | B13: Thursday, March 21, 2024 | C13: 1 | D13: IndustrialPC | E13: IB_2RS232_E1N002INF1_BOM.xlsx | F13: 2 | G13: 12 | I13: IC REG LINEAR 3.3V 150MA SOT89-3L | J13: RS3005-3.3YE3L | K13: Runic | L13: Runic:RS3005-3.3YE3L | M13: 10433 | N13: 1 | O13: D4
... A22: IB_2RS232_E1N002INF1 | B22: Thursday, March 21, 2024 | C22: 1 | D22: IndustrialPC | E22: IB_2RS232_E1N002INF1_BOM.xlsx | F22: 2 | G22: 21 | I22: FIXED IND 10UH 770MA 345MOHM SMD | J22: SWPA4012S100MT | K22: Sunlord | L22: Sunlord:SWPA4012S100MT | M22: 10416 | N22: 3 | O22: L6, L8, L10
A23: IB_2RS232_E1N002INF1 | B23: Thursday, March 21, 2024 | C23: 1 | D23: IndustrialPC | E23: IB_2RS232_E1N002INF1_BOM.xlsx | F23: 2 | G23: 22 | I23: Test pin | M23: 1135 | N23: 1 | O23: P23, P24, P25, P26, P29, P30, P31
A24: IB_2RS232_E1N002INF1 | B24: Thursday, March 21, 2024 | C24: 1 | D24: IndustrialPC | E24: IB_2RS232_E1N002INF1_BOM.xlsx | F24: 2 | G24: 23 | I24: RES SMD 0ohm +/-5% 1/16W 0402 | J24: AC0402JR-070RL | K24: Yageo | L24: Yageo:AC0402JR-070RL | M24: 16369 | N24: 1 | O24: R1
A25: IB_2RS232_E1N002INF1 | B25: Thursday, March 21, 2024 | C25: 1 | D25: IndustrialPC | E25: IB_2RS232_E1N002INF1_BOM.xlsx | F25: 2 | G25: 24 | I25: RES SMD 470kohm +/-1% 1/16W 0402 | J25: RC0402FR-07470KL | K25: Yageo | L25: Yageo:RC0402FR-07470KL | M25: 40031 | N25: 2 | O25: R2, R6
A26: IB_2RS232_E1N002INF1 | B26: Thursday, March 21, 2024 | C26: 1 | D26: IndustrialPC | E26: IB_2RS232_E1N002INF1_BOM.xlsx | F26: 2 | G26: 25 | I26: RES SMD 33ohm +/-1% 1/16W 0402 | J26: AC0402FR-0733RL | K26: Yageo | L26: Yageo:AC0402FR-0733RL | M26: 15165 | N26: 2 | O26: R3, R33
A27: IB_2RS232_E1N002INF1 | B27: Thursday, March 21, 2024 | C27: 1 | D27: IndustrialPC | E27: IB_2RS232_E1N002INF1_BOM.xlsx | F27: 2 | G27: 26 | I27: RES SMD 1kohm +/-1% 1/16W 0402 | J27: AC0402FR-071KL | K27: Yageo | L27: Yageo:AC0402FR-071KL | M27: 14934 | N27: 2 | O27: R4, R11
A28: IB_2RS232_E1N002INF1 | B28: Thursday, March 21, 2024 | C28: 1 | D28: IndustrialPC | E28: IB_2RS232_E1N002INF1_BOM.xlsx | F28: 2 | G28: 27 | I28: RES SMD 12kohm +/-1% 1/16W 0402 | J28: RC0402FR-0712KL | K28: Yageo | L28: Yageo:RC0402FR-0712KL | M28: 39560 | N28: 10 | O28: R5, R8, R9, R10, R18, R21, R24, R25, R26, R32
A29: IB_2RS232_E1N002INF1 | B29: Thursday, March 21, 2024 | C29: 1 | D29: IndustrialPC | E29: IB_2RS232_E1N002INF1_BOM.xlsx | F29: 2 | G29: 28 | I29: RES SMD 100kohm +/-1% 1/16W 0402 | J29: RC0402FR-07100KL | K29: Yageo | L29: Yageo:RC0402FR-07100KL | M29: 39516 | N29: 9 | O29: R7, R13, R15, R16, R27, R28, R29, R30, R31
A30: IB_2RS232_E1N002INF1 | B30: Thursday, March 21, 2024 | C30: 1 | D30: IndustrialPC | E30: IB_2RS232_E1N002INF1_BOM.xlsx | F30: 2 | G30: 29 | I30: RES SMD 270ohm +/-1% 1/2W 1210 | J30: AC1210FR-07270RL | K30: Yageo | L30: Yageo:AC1210FR-07270RL | M30: 27546 | N30: 3 | O30: R12, R14, R17
A31: IB_2RS232_E1N002INF1 | B31: Thursday, March 21, 2024 | C31: 1 | D31: IndustrialPC | E31: IB_2RS232_E1N002INF1_BOM.xlsx | F31: 2 | G31: 30 | I31: RES , 0402, 0ohms, 1/16W | J31: RC0402JR-070RL | K31: Yageo | L31: Yageo:RC0402JR-070RL | M31: 8610 | N31: 4 | O31: R19, R20, R22, R23
A32: IB_2RS232_E1N002INF1 | B32: Thursday, March 21, 2024 | C32: 1 | D32: IndustrialPC | E32: IB_2RS232_E1N002INF1_BOM.xlsx | F32: 2 | G32: 31 | I32: LED 2V 20mA 571nm GREEN COLOR SMD 0603 | J32: LTST-C190KGKT | K32: Lite-On Electronics Inc | L32: Lite-On Electronics Inc:LTST-C190KGKT | M32: 8576 | N32: 2 | O32: VD1, VD2
A33: IB_2RS232_E1N002INF1 | B33: Thursday, March 21, 2024 | C33: 1 | D33: IndustrialPC | E33: IB_2RS232_E1N002INF1_BOM.xlsx | F33: 2 | G33: 32 | I33: TVS DIODE 5VWM 18.6VC SOD523 | J33: ESD5Z5.0T1G | K33: On Semiconductor | L33: On Semiconductor:ESD5Z5.0T1G | M33: 10350 | N33: 3 | O33: VD3, VD4, VD5
A34: IB_2RS232_E1N002INF1 | B34: Thursday, March 21, 2024 | C34: 1 | D34: IndustrialPC | E34: IB_2RS232_E1N002INF1_BOM.xlsx | F34: 2 | G34: 33 | I34: TVS Diode | J34: ESD12VB7-1006 | K34: Tech Public | L34: Tech Public:ESD12VB7-1006 | M34: 10364 | N34: 10 | O34: VD6, VD7, VD8, VD9, VD10, VD11, VD12, VD13, VD15, VD16
A35: IB_2RS232_E1N002INF1 | B35: Thursday, March 21, 2024 | C35: 1 | D35: IndustrialPC | E35: IB_2RS232_E1N002INF1_BOM.xlsx | F35: 2 | G35: 34 | I35: DIODE SCHOTTKY 30V 100MA SOD323 | J35: BAT54WS | K35: SMC | L35: SMC:BAT54WS | M35: 42433 | N35: 1 | O35: VD14
... A37: IB_2RS232_E1N002INF1 | B37: Thursday, March 21, 2024 | C37: 1 | D37: IndustrialPC | E37: IB_2RS232_E1N002INF1_BOM.xlsx | F37: 2 | G37: 36 | I37: CONN Double row 1.25mm wire to board connector | J37: L-KLS1-XL4-1.25-2-10-VM | K37: KLS | L37: KLS:L-KLS1-XL4-1.25-2-10-VM | M37: 10415 | N37: 4 | O37: X1, X2, X3, X4
N38: =SUM(N2:N37) -> 202

Sheet PCIe104_INF_E1N001INF1
A1: ID | B1: Date | C1: N | D1: Type | E1: File | F1: Count | G1: # | H1: Analog | I1: Description | J1: Manufacturer part number | K1: Mfg name | L1: Mfg part number | M1: Part number | N1: Qty | O1: Ref designator | P1: Qty2
A2: PCIe104_INF_E1N001INF1 | B2: Thursday, May 16, 2024 | C2: 2 | D2: ModulePC | E2: PCIE104-INF_E1N001INF1E_MAIN.xlsx | F2: 1 | G2: 1 | I2: CRYSTAL 25.0000MHZ 12PF | J2: ABM8-25.000MHZ-12-D1X-T | K2: Abracon Corporation | L2: Abracon Corporation:ABM8-25.000MHZ-12-D1X-T | M2: 10385 | N2: 5 | O2: BQ1,BQ3,BQ4,BQ5,BQ6 | P2: 5
A3: PCIe104_INF_E1N001INF1 | B3: Thursday, May 16, 2024 | C3: 2 | D3: ModulePC | E3: PCIE104-INF_E1N001INF1E_MAIN.xlsx | F3: 1 | G3: 2 | I3: CRYSTAL 12.0000MHZ 8PF SMD | J3: ABM8W-12.0000MHZ-8-D1X-T3 | K3: Abracon Corporation | L3: Abracon Corporation:ABM8W-12.0000MHZ-8-D1X-T3 | M3: 10191 | N3: 2 | O3: BQ2,BQ9 | P3: 2
A4: PCIe104_INF_E1N001INF1 | B4: Thursday, May 16, 2024 | C4: 2 | D4: ModulePC | E4: PCIE104-INF_E1N001INF1E_MAIN.xlsx | F4: 1 | G4: 3 | I4: CRYSTAL 24.0000MHZ 18PF SMD | J4: ABM8-24.000MHZ-D1G-T | K4: Abracon Corporation | L4: Abracon Corporation:ABM8-24.000MHZ-D1G-T | M4: 42397 | N4: 1 | O4: BQ7 | P4: 1
A5: PCIe104_INF_E1N001INF1 | B5: Thursday, May 16, 2024 | C5: 2 | D5: ModulePC | E5: PCIE104-INF_E1N001INF1E_MAIN.xlsx | F5: 1 | G5: 4 | I5: CAP CER, 0805, 47uF, 6.3V, X6S, +/-20% | J5: MSASJ21GBC6476MTNA01 | K5: Taiyo Yuden | L5: Taiyo Yuden:MSASJ21GBC6476MTNA01 | M5: 42376 | N5: 6 | O5: C1,C2,C3,C4,C133,C377 | P5: 6
A6: PCIe104_INF_E1N001INF1 | B6: Thursday, May 16, 2024 | C6: 2 | D6: ModulePC | E6: PCIE104-INF_E1N001INF1E_MAIN.xlsx | F6: 1 | G6: 5 | I6: CAP CER 0603 6.3V 22uF X6S +/-20% | J6: CC0603MRX6S5BB226 | K6: Yageo | L6: Yageo:CC0603MRX6S5BB226 | M6: 42512 | N6: 14 | O6: C5,C6,C40,C41,C42,C43,C77,C78,C79,C80,C107,C108,C109,C181 | P6: 14
A7: PCIe104_INF_E1N001INF1 | B7: Thursday, May 16, 2024 | C7: 2 | D7: ModulePC | E7: PCIE104-INF_E1N001INF1E_MAIN.xlsx | F7: 1 | G7: 6 | I7: CAP CER 0805 16 V 22 uF X6S В±20% | J7: C2012X6S1C226M125AC | K7: TDK | L7: TDK:C2012X6S1C226M125AC | M7: 42386 | N7: 30 | O7: C7,C8,C9,C10,C29,C36,C37,C82,C83,C84,C86,C87,C88,C89,C91,C92,C93,C94,C95,C96,C97,C98,C99,C131,C173,C174,C175,C176,C178,C179 | P7: 30
A8: PCIe104_INF_E1N001INF1 | B8: Thursday, May 16, 2024 | C8: 2 | D8: ModulePC | E8: PCIE104-INF_E1N001INF1E_MAIN.xlsx | F8: 1 | G8: 7 | I8: CAP CER 0201 16V 0.1uF X6S +/-10% | J8: C0603X6S1C104K030BC | K8: TDK | L8: TDK:C0603X6S1C104K030BC | M8: 42485 | N8: 102 | O8: C11,C44,C45,C46,C47,C48,C49,C50,C51,C55,C67,C68,C69,C70,C71,C72,C73,C74,C81,C85,C100,C104,C105,C106,C110,C111,C112,C113,C114,C115,C116,C117,C118,C119,C120,C121,C172,C180,C192,C193,C194,C195,C209,C210,C212,C213,C214,C215,C268,C269,C270,C271,C273,C274,C288,C289,C290,C291,C292,C301,C302,C303,C304,C305,C341,C342,C343,C344,C347,C379,C381,C388,C389,C390,C391,C392,C393,C400,C401,C402,C403,C404,C405,C406,C409,C558,C733,C734,C735,C736,C737,C738,C739,C740,C741,C742,C743,C744,C745,C746,C747,C748 | P8: 102
A9: PCIe104_INF_E1N001INF1 | B9: Thursday, May 16, 2024 | C9: 2 | D9: ModulePC | E9: PCIE104-INF_E1N001INF1E_MAIN.xlsx | F9: 1 | G9: 8 | I9: CAP CER 0201 10V 0.22uF X6S +/-10% | J9: C0603X6S1A224K030BC | K9: TDK | L9: TDK:C0603X6S1A224K030BC | M9: 42429 | N9: 108 | O9: C12,C13,C14,C15,C16,C17,C18,C19,C20,C21,C22,C23,C24,C25,C30,C31,C32,C33,C34,C35,C90,C168,C169,C182,C183,C184,C185,C186,C187,C188,C189,C190,C191,C196,C197,C198,C199,C202,C203,C204,C205,C206,C207,C208,C232,C256,C293,C294,C306,C307,C353,C354,C355,C356,C357,C358,C359,C722,C723,C724,C775,C776,C777,C778,C779,C780,C781,C782,C783,C784,C785,C786,C787,C788,C789,C790,C791,C792,C793,C794,C795,C796,C797,C798,C799,C800,C801,C802,C803,C804,C805,C806,C807,C808,C811,C812,C813,C814,C815,C816,C819,C820,C821,C822,C823,C824,C825,C826 | P9: 108
A10: PCIe104_INF_E1N001INF1 | B10: Thursday, May 16, 2024 | C10: 2 | D10: ModulePC | E10: PCIE104-INF_E1N001INF1E_MAIN.xlsx | F10: 1 | G10: 9 | I10: CAP CER 0201 10V 1uF X6S +/-20% | J10: CM03X6S105M10AH | K10: Kyocera | L10: Kyocera:CM03X6S105M10AH | M10: 42491 | N10: 29 | O10: C26,C28,C142,C143,C144,C145,C146,C147,C148,C149,C150,C151,C152,C153,C154,C155,C156,C157,C158,C159,C160,C161,C162,C163,C164,C165,C166,C167,C350 | P10: 29
A11: PCIe104_INF_E1N001INF1 | B11: Thursday, May 16, 2024 | C11: 2 | D11: ModulePC | E11: PCIE104-INF_E1N001INF1E_MAIN.xlsx | F11: 1 | G11: 10 | I11: CAP CER 0603 16V 10uF X6S +/-20% | J11: CL10X106MO8NRN | K11: Samsung | L11: Samsung:CL10X106MO8NRN | M11: 42431 | N11: 17 | O11: C27,C225,C226,C228,C229,C230,C351,C352,C758,C759,C760,C761,C762,C763,C764,C765,C766 | P11: 17
A12: PCIe104_INF_E1N001INF1 | B12: Thursday, May 16, 2024 | C12: 2 | D12: ModulePC | E12: PCIE104-INF_E1N001INF1E_MAIN.xlsx | F12: 1 | G12: 11 | I12: CAP CER 0402 25V 120pF C0G/NP0 +/-5% | J12: 0402N121J250CT | K12: Walsin Technology Corp. | L12: Walsin:0402N121J250CT | M12: 42556 | N12: 2 | O12: C38,C39 | P12: 2
A13: PCIe104_INF_E1N001INF1 | B13: Thursday, May 16, 2024 | C13: 2 | D13: ModulePC | E13: PCIE104-INF_E1N001INF1E_MAIN.xlsx | F13: 1 | G13: 12 | I13: CAP CER 0402 16V 2.2uF X6S +/-10% | J13: C1005X6S1C225K050BC | K13: TDK | L13: TDK:C1005X6S1C225K050BC | M13: 42476 | N13: 5 | O13: C52,C135,C707,C708,C709 | P13: 5
... A71: PCIe104_INF_E1N001INF1 | B71: Thursday, May 16, 2024 | C71: 2 | D71: ModulePC | E71: PCIE104-INF_E1N001INF1E_MAIN.xlsx | F71: 1 | G71: 70 | I71: IND 1uH +/-20% 12.2A 7.6mOhm 5.5x5.3x3.1mm SMD | J71: PA5003.102NLT | K71: Pulse Electronics Corporation | L71: Pulse Electronics Corporation:PA5003.102NLT | M71: 42525 | N71: 1 | O71: L8 | P71: 1
A72: PCIe104_INF_E1N001INF1 | B72: Thursday, May 16, 2024 | C72: 2 | D72: ModulePC | E72: PCIE104-INF_E1N001INF1E_MAIN.xlsx | F72: 1 | G72: 71 | I72: IND, 0201, 80 ohms, 1,2 A, DCR 95 mOhm | M72: 10520 | N72: 8 | O72: L9,L19,L29,L32,L35,L38,L39,L90 | P72: 8
A73: PCIe104_INF_E1N001INF1 | B73: Thursday, May 16, 2024 | C73: 2 | D73: ModulePC | E73: PCIE104-INF_E1N001INF1E_MAIN.xlsx | F73: 1 | G73: 72 | I73: IND, 3.3uH, +/-30%, 3.4A, 24mOhm, 5x5x4.2mm SMD | J73: TYS50403R3N-10 | K73: Laird Technologies | L73: Laird:TYS50403R3N-10 | M73: 33855 | N73: 2 | O73: L11,L14 | P73: 2
A74: PCIe104_INF_E1N001INF1 | B74: Thursday, May 16, 2024 | C74: 2 | D74: ModulePC | E74: PCIE104-INF_E1N001INF1E_MAIN.xlsx | F74: 1 | G74: 73 | I74: FIXED IND 10UH 770MA 345MOHM SMD | J74: SWPA4012S100MT | K74: Sunlord | L74: Sunlord:SWPA4012S100MT | M74: 10416 | N74: 3 | O74: L12,L91,L92 | P74: 3
A75: PCIe104_INF_E1N001INF1 | B75: Thursday, May 16, 2024 | C75: 2 | D75: ModulePC | E75: PCIE104-INF_E1N001INF1E_MAIN.xlsx | F75: 1 | G75: 74 | I75: 300 Ohm 400mA, Common mode choke coil | J75: SDCW2520S-2-301TF | K75: Sunlord | L75: Sunlord:SDCW2520S-2-301TF | M75: 10354 | N75: 1 | O75: L13 | P75: 1
A76: PCIe104_INF_E1N001INF1 | B76: Thursday, May 16, 2024 | C76: 2 | D76: ModulePC | E76: PCIE104-INF_E1N001INF1E_MAIN.xlsx | F76: 1 | G76: 75 | I76: IND, 0201, 22Ohms, 1.9A, DCR 36mOhm | J76: MPZ0603S220HT000 | K76: TDK | L76: TDK:MPZ0603S220HT000 | M76: 33933 | N76: 8 | O76: L15,L18,L30,L31,L33,L34,L36,L37 | P76: 8
A77: PCIe104_INF_E1N001INF1 | B77: Thursday, May 16, 2024 | C77: 2 | D77: ModulePC | E77: PCIE104-INF_E1N001INF1E_MAIN.xlsx | F77: 1 | G77: 76 | I77: IND, 1uH, +/-20%, 4.1A , 22mOhm, 1210 SMD | J77: DFE32CAH1R0MR0L | K77: Murata | L77: Murata:DFE32CAH1R0MR0L | M77: 42360 | N77: 2 | O77: L16,L17 | P77: 2
A78: PCIe104_INF_E1N001INF1 | B78: Thursday, May 16, 2024 | C78: 2 | D78: ModulePC | E78: PCIE104-INF_E1N001INF1E_MAIN.xlsx | F78: 1 | G78: 77 | I78: IND, 0201, 600Ohm, 280mA, DCR 0.75Ohm | M78: 42481 | N78: 16 | O78: L21,L22,L23,L24,L25,L26,L27,L28,L79,L80,L81,L82,L83,L84,L85,L86 | P78: 16
A79: PCIe104_INF_E1N001INF1 | B79: Thursday, May 16, 2024 | C79: 2 | D79: ModulePC | E79: PCIE104-INF_E1N001INF1E_MAIN.xlsx | F79: 1 | G79: 78 | I79: Test Points, 1mm DIA | M79: 10295 | N79: 26 | O79: P1,P2,P3,P4,P6,P7,P30,P31,P39,TP1,TP2,TP3,TP4,TP5,TP6,TP7,TP8,TP9,TP10,TP11,TP12,TP13,TP14,TP15,TP16,TP17 | P79: 26
